<?xml version='1.0'?>
<robot name="miniBox">

    <!-- Base Link -->
    <link name="base_link">
        <visual>
        <origin xyz="0 0 0" rpy="0 0 0" />
        <geometry>
            <cylinder length="0.01" radius="0.25" />
        </geometry>
        <material name="white">
            <color rgba="0.90 0.91 0.95 1"/>
        </material>
        </visual>
        <!-- Base collision, mass and inertia -->
        <collision>
            <origin xyz="0 0 0" rpy="0 0 0" />
            <geometry>
                <cylinder length="0.01" radius="0.25" />
            </geometry>
        </collision>
            <inertial>
            <mass value="60"/>
          <inertia ixx="0.019995" ixy="0.0" ixz="0.0" iyy="0.019995" iyz="0.0" izz="0.03675"/>

        </inertial>
    </link>

    <link name="top_link">
        <visual>
        <origin xyz="0 0 0" rpy="0 0 0" />
        <geometry>
            <cylinder length="0.8" radius="0.25" />
        </geometry>
        <material name="white">
            <color rgba="0.90 0.91 0.95 1"/>
        </material>
        </visual>
        <!-- Base collision, mass and inertia -->
        <collision>
            <origin xyz="0 0 0" rpy="0 0 0" />
            <geometry>
                <cylinder length="0.8" radius="0.25" />
            </geometry>
        </collision>
        <inertial>
            <mass value="60"/>
            <inertia ixx="100" ixy="0.0" ixz="0.0" iyy="100" iyz="0.0" izz="100"/>
        </inertial>
    </link>

    <!-- Top joint -->
    <joint name="joint_top" type="continuous">
        <parent link="base_link"/>
        <child link="top_link"/>
        <origin xyz="0 0 0.4" rpy="0 0 0" />
        <axis xyz="0 1 0" />
    </joint>

    <!-- Right Wheel -->
    <link name="right_wheel">
        <visual>
        <origin xyz="0 0 0" rpy="1.570795 0 0" />
        <geometry>
            <cylinder length="0.1" radius="0.1" />
        </geometry>
        <material name="darkgray">
            <color rgba="0.2 0.2 0.2 1"/>
        </material>
        </visual>
        <!-- Right Wheel collision, mass and inertia -->
        <collision>
            <origin xyz="0 0 0" rpy="1.570795 0 0" />
            <geometry>
                <cylinder length="0.1" radius="0.1" />
            </geometry>
        </collision>
        <inertial>
            <mass value="0.5"/>
            <inertia ixx="0.01" ixy="0.0" ixz="0.0" iyy="0.005" iyz="0.0" izz="0.005"/>
        </inertial>

    </link>

    <!-- Right Wheel joint -->
    <joint name="joint_right_wheel" type="continuous">
        <parent link="base_link"/>
        <child link="right_wheel"/>
        <origin xyz="0 -0.115 0.09" rpy="0 0 0" />
        <axis xyz="0 1 0" />
    </joint>

    <!-- Left Wheel -->
    <link name="left_wheel">
        <visual>
        <origin xyz="0 0 0" rpy="1.570795 0 0" />
        <geometry>
            <cylinder length="0.1" radius="0.1" />
        </geometry>
        <material name="darkgray">
            <color rgba="0.2 0.2 0.2 1"/>
        </material>
        </visual>
        <!-- Left Wheel collision, mass and inertia -->
        <collision>
            <origin xyz="0 0 0" rpy="1.570795 0 0" />
            <geometry>
                <cylinder length="0.1" radius="0.1" />
            </geometry>
        </collision>
        <inertial>
            <mass value="0.5"/>
            <inertia ixx="0.01" ixy="0.0" ixz="0.0" iyy="0.005" iyz="0.0" izz="0.005"/>
        </inertial>
    </link>

    <!-- Left Wheel joint -->
    <joint name="joint_left_wheel" type="continuous">
        <parent link="base_link"/>
        <child link="left_wheel"/>
        <origin xyz="0 0.115 0.09" rpy="0 0 0" />
        <axis xyz="0 1 0" />
    </joint>
</robot>